Workbook

Sheet NEW_METRICS
B1: Customer Need | C1: Importance | D1: Metric 1 | E1: Unit 1 | F1: Metric 2 | G1: Unit 2
B2: The system should enable quick and efficient water transfer from the tank to the garden. | C2: 5 | D2: Water Transfer Rate | E2: Liters per minute (L/min) | F2: Time to Water Garden | G2: Minutes
B3: The system should provide consistent and reliable water distribution across the entire garden area. | C3: 5 | D3: Distribution Uniformity | E3: Percentage (%) | F3: Soil Moisture Variation | G3: % volumetric water content
B4: The system should minimize manual labor and physical effort required to operate. | C4: 4 | D4: Manual Operations Count | E4: Count | F4: Operational Effort Time | G4: Minutes
B5: The system should provide sufficient water pressure for effective delivery. | C5: 4 | D5: Water Pressure at Delivery | E5: Kilopascals (kPa)
B6: The system should maintain adequate flow rate for different watering methods. | C6: 4 | D6: Flow Rate per Method | E6: Liters per minute (L/min) | F6: Flow Rate Consistency | G6: Percentage (%) variation
B7: The system should function efficiently with varying water levels in the tank. | C7: 3 | D7: Performance at Varying Levels | E7: L/min and kPa at different levels | F7: Minimum Operational Water Level | G7: Liters (L)
B8: The system should be easy to operate for users without technical expertise. | C8: 4 | D8: Learning Time for New Users | E8: Minutes | F8: User Error Rate | G8: Errors per operation cycle
B9: The system should have straightforward controls for starting, stopping, and adjusting as needed. | C9: 3 | D9: Control Interface Count | E9: Count | F9: Operation Initiation Time | G9: Seconds
B10: The system should provide clear instructions and minimize operational steps. | C10: 3 | D10: Instruction Steps Count | E10: Count | F10: Instruction Clarity Rating | G10: Likert scale units (1–5)
B11: The system should require minimal maintenance for reliable operation. | C11: 4 | D11: Maintenance Frequency | E11: Times per year | F11: Maintenance Duration | G11: Minutes
B12: The system should be durable and resistant to wear and tear under normal conditions. | C12: 4 | D12: Expected Lifespan | E12: Years | F12: Warranty Period | G12: Years
B13: The system should allow easy troubleshooting of common issues. | C13: 3 | D13: Troubleshooting Time | E13: Minutes | F13: Diagnostic Tools Availability | G13: Yes/No
B14: The system should minimize environmental impact and align with sustainability goals. | C14: 4 | D14: Eco-Friendly Materials % | E14: Percentage (%) | F14: Potable Water Savings | G14: Liters per month
B15: The system should be compatible with rainwater harvesting practices. | C15: 3 | D15: Rainwater Utilization Rate | E15: Percentage (%) | F15: Compatibility Status | G15: Yes/No
B16: The system should be designed to minimize noise pollution. | C16: 3 | D16: Operating Noise Level | E16: Decibels (dB) | F16: Peak Noise Level | G16: Decibels (dB)
B17: The system should be cost-effective to implement within the given budget. | C17: 4 | D17: Initial Implementation Cost | E17: Dollars ($) | F17: Cost per Garden Area | G17: Dollars per square meter ($/m²)
... B22: The system should be safe to operate under various weather conditions. | C22: 4 | D22: Operational Temperature Range | E22: Degrees Celsius (°C) | F22: Weather Resistance Rating | G22: IP Rating (e.g., IP65)
B27: Customer Need | C27: Importance | D27: Metric | E27: Unit
B28: The system should enable quick and efficient water transfer from the tank to the garden. | C28: 5 | D28: Water Transfer Rate | E28: Liters per minute (L/min)
D29: Time to Water Garden | E29: Minutes
B30: The system should provide consistent and reliable water distribution across the entire garden area. | C30: 5 | D30: Distribution Uniformity | E30: Percentage (%)
D31: Soil Moisture Variation | E31: % volumetric water content
B32: The system should minimize manual labor and physical effort required to operate. | C32: 4 | D32: Manual Operations Count | E32: Count
D33: Operational Effort Time | E33: Minutes
B34: The system should provide sufficient water pressure for effective delivery. | C34: 4 | D34: Water Pressure at Delivery | E34: Kilopascals (kPa)
B35: The system should maintain adequate flow rate for different watering methods. | C35: 4 | D35: Flow Rate per Method | E35: Liters per minute (L/min)
D36: Flow Rate Consistency | E36: Percentage (%) variation
B37: The system should function efficiently with varying water levels in the tank. | C37: 3 | D37: Performance at Varying Levels | E37: L/min and kPa at different levels
D38: Minimum Operational Water Level | E38: Liters (L)
B39: The system should be easy to operate for users without technical expertise. | C39: 4 | D39: Learning Time for New Users | E39: Minutes
D40: User Error Rate | E40: Errors per operation cycle
B41: The system should have straightforward controls for starting, stopping, and adjusting as needed. | C41: 3 | D41: Control Interface Count | E41: Count
D42: Operation Initiation Time | E42: Seconds
B43: The system should provide clear instructions and minimize operational steps. | C43: 3 | D43: Instruction Steps Count | E43: Count
D44: Instruction Clarity Rating | E44: Likert scale units (1–5)
B45: The system should require minimal maintenance for reliable operation. | C45: 4 | D45: Maintenance Frequency | E45: Times per year
D46: Maintenance Duration | E46: Minutes
B47: The system should be durable and resistant to wear and tear under normal conditions. | C47: 4 | D47: Expected Lifespan | E47: Years
D48: Warranty Period | E48: Years
...

Sheet Competitor assesment
B2: Requirements | C2: GARDENA 2000/2 | D2: Bosch GardenPump 18V | E2: Kärcher BP 2.000-18 | F2: VPC Pump A Way Manual Pump | G2: EZ Crank Manual Water Pump | H2: Gardener's Rain Barrel Hand Pump | I2: RainPerfect Solar Pump | J2: RainFlo Solar Pump System | K2: Rule Solar Powered Pump
C3: Battery | F3: Manual | I3: Solar
B4: Quick and Efficient Water Transfer | C4: 5 | D4: 5 | E4: 5 | F4: 3 | G4: 4 | H4: 3 | I4: 4 | J4: 5 | K4: 4
B5: Consistent and Reliable Water Distribution | C5: 5 | D5: 5 | E5: 5 | F5: 3 | G5: 4 | H5: 3 | I5: 4 | J5: 5 | K5: 4
B6: Minimize Manual Labor | C6: 5 | D6: 5 | E6: 5 | F6: 2 | G6: 2 | H6: 2 | I6: 5 | J6: 5 | K6: 5
B7: Sufficient Water Pressure | C7: 5 | D7: 5 | E7: 5 | F7: 2 | G7: 4 | H7: 3 | I7: 4 | J7: 5 | K7: 4
B8: Flow Rate for Different Watering Methods | C8: 5 | D8: 5 | E8: 5 | F8: 3 | G8: 4 | H8: 3 | I8: 4 | J8: 5 | K8: 4
B9: Efficient Functioning with Varying Water Levels | C9: 5 | D9: 5 | E9: 5 | F9: 3 | G9: 4 | H9: 3 | I9: 4 | J9: 5 | K9: 4
B10: Ease of Operation | C10: 5 | D10: 5 | E10: 5 | F10: 4 | G10: 4 | H10: 4 | I10: 5 | J10: 5 | K10: 5
B11: Straightforward Controls and Minimal Operational Steps | C11: 5 | D11: 5 | E11: 5 | F11: 4 | G11: 4 | H11: 4 | I11: 5 | J11: 5 | K11: 5
B12: Minimal Maintenance | C12: 4 | D12: 4 | E12: 4 | F12: 5 | G12: 5 | H12: 5 | I12: 5 | J12: 5 | K12: 5
B13: Durability | C13: 4 | D13: 4 | E13: 4 | F13: 4 | G13: 5 | H13: 4 | I13: 4 | J13: 5 | K13: 4
B14: Easy Troubleshooting | C14: 4 | D14: 4 | E14: 4 | F14: 5 | G14: 5 | H14: 5 | I14: 4 | J14: 4 | K14: 4
B15: Minimize Environmental Impact | C15: 5 | D15: 5 | E15: 5 | F15: 5 | G15: 5 | H15: 5 | I15: 5 | J15: 5 | K15: 5
... B21: Safe to Operate in Various Weather Conditions | C21: 5 | D21: 5 | E21: 5 | F21: 5 | G21: 5 | H21: 5 | I21: 5 | J21: 5 | K21: 5

Sheet CR-TR interactions
A1: Units | C1: L/min | D1: Minutes | E1: % | F1: % water | G1: Count | H1: Minutes | I1: Borg Scale | J1: kPa | K1: L/min | L1: % variation | M1: L/min and kPa | N1: Liters | O1: Minutes | P1: Errors/op cycle | Q1: Count | R1: Seconds | S1: Count | T1: Likert scale | U1: Times per year | V1: Minutes | W1: Years | X1: Years | Y1: Minutes | Z1: Yes/No | AA1: % | AB1: Liters/month | AC1: % | AD1: Yes/No | AE1: dB | AF1: $ | AG1: $/m² | AH1: $/year | AI1: $ | AJ1: $/year | AK1: % | AL1: Count | AM1: Yes/No | AN1: Count | AO1: low/hi | AP1: °C
A2: CR#/TR# | C2: Water Transfer Rate | D2: Time to Water Garden | E2: Distribution Uniformity | F2: Soil Moisture Variation | G2: Manual Operations Count | H2: Operational Effort Time | I2: Physical Exertion Level | J2: Water Pressure at Delivery | K2: Flow Rate per Method | L2: Flow Rate Consistency | M2: Performance at Varying Levels | N2: Minimum Operational Water Level | O2: Learning Time for New Users | P2: User Error Rate | Q2: Control Interface Count | R2: Operation Initiation Time | S2: Instruction Steps Count | T2: Instruction Clarity Rating | U2: Maintenance Frequency | V2: Maintenance Duration | W2: Expected Lifespan | X2: Warranty Period | Y2: Troubleshooting Time | Z2: Diagnostic Tools Availability | AA2: Eco-Friendly Materials % | AB2: Potable Water Savings | AC2: Rainwater Utilization Rate | AD2: Compatibility Status | AE2: Operating Noise Level | AF2: Initial Implementation Cost | AG2: Cost per Garden Area | AH2: Annual Operational Cost | AI2: Total Cost of Ownership | AJ2: Cost per Year of Lifespan | AK2: Water Use Efficiency | AL2: Standards Compliance Count | AM2: Certification Status | AN2: Hazard Count | AO2: Risk Assessment Score | AP2: Operational Temperature Range
A3: CR1 | B3: 5 | C3: 9 | D3: 9 | E3: 3 | F3: 3 | G3: 1 | H3: 1 | I3: 1 | J3: 9 | K3: 3 | L3: 3 | M3: 1 | N3: 0 | O3: 0 | P3: 0 | Q3: 1 | R3: 1 | S3: 0 | T3: 0 | U3: 0 | V3: 0 | W3: 0 | X3: 0 | Y3: 0 | Z3: 0 | AA3: 1 | AB3: 1 | AC3: 0 | AD3: 0 | AE3: 0 | AF3: 1 | AG3: 1 | AH3: 0 | AI3: 0 | AJ3: 0 | AK3: 3 | AL3: 1 | AM3: 1 | AN3: 1 | AO3: 0 | AP3: 0
A4: CR2 | B4: 5 | C4: 3 | D4: 3 | E4: 9 | F4: 9 | G4: 1 | H4: 1 | I4: 1 | J4: 3 | K4: 9 | L4: 3 | M4: 1 | N4: 0 | O4: 0 | P4: 0 | Q4: 1 | R4: 1 | S4: 0 | T4: 0 | U4: 0 | V4: 0 | W4: 0 | X4: 0 | Y4: 0 | Z4: 0 | AA4: 1 | AB4: 1 | AC4: 0 | AD4: 0 | AE4: 0 | AF4: 1 | AG4: 1 | AH4: 0 | AI4: 0 | AJ4: 0 | AK4: 9 | AL4: 1 | AM4: 1 | AN4: 1 | AO4: 0 | AP4: 0
A5: CR3 | B5: 4 | C5: 1 | D5: 1 | E5: 0 | F5: 0 | G5: 9 | H5: 9 | I5: 3 | J5: 1 | K5: 1 | L5: 1 | M5: 1 | N5: 3 | O5: 3 | P5: 1 | Q5: 9 | R5: 9 | S5: 0 | T5: 0 | U5: 0 | V5: 0 | W5: 0 | X5: 0 | Y5: 0 | Z5: 0 | AA5: 1 | AB5: 1 | AC5: 0 | AD5: 0 | AE5: 0 | AF5: 3 | AG5: 3 | AH5: 1 | AI5: 1 | AJ5: 1 | AK5: 3 | AL5: 1 | AM5: 1 | AN5: 1 | AO5: 0 | AP5: 0
A6: CR4 | B6: 4 | C6: 3 | D6: 3 | E6: 3 | F6: 3 | G6: 1 | H6: 1 | I6: 1 | J6: 9 | K6: 9 | L6: 3 | M6: 1 | N6: 0 | O6: 0 | P6: 0 | Q6: 1 | R6: 1 | S6: 0 | T6: 0 | U6: 0 | V6: 0 | W6: 0 | X6: 0 | Y6: 0 | Z6: 0 | AA6: 1 | AB6: 1 | AC6: 0 | AD6: 0 | AE6: 0 | AF6: 1 | AG6: 1 | AH6: 0 | AI6: 0 | AJ6: 0 | AK6: 3 | AL6: 1 | AM6: 1 | AN6: 1 | AO6: 0 | AP6: 0
A7: CR5 | B7: 4 | C7: 3 | D7: 3 | E7: 3 | F7: 3 | G7: 1 | H7: 1 | I7: 1 | J7: 3 | K7: 9 | L7: 9 | M7: 1 | N7: 0 | O7: 0 | P7: 0 | Q7: 1 | R7: 1 | S7: 0 | T7: 0 | U7: 0 | V7: 0 | W7: 0 | X7: 0 | Y7: 0 | Z7: 0 | AA7: 1 | AB7: 1 | AC7: 0 | AD7: 0 | AE7: 0 | AF7: 1 | AG7: 1 | AH7: 0 | AI7: 0 | AJ7: 0 | AK7: 9 | AL7: 1 | AM7: 1 | AN7: 1 | AO7: 0 | AP7: 0
A8: CR6 | B8: 3 | C8: 1 | D8: 1 | E8: 1 | F8: 1 | G8: 0 | H8: 0 | I8: 0 | J8: 3 | K8: 3 | L8: 3 | M8: 9 | N8: 9 | O8: 0 | P8: 0 | Q8: 1 | R8: 1 | S8: 0 | T8: 0 | U8: 0 | V8: 0 | W8: 0 | X8: 0 | Y8: 0 | Z8: 0 | AA8: 1 | AB8: 1 | AC8: 9 | AD8: 9 | AE8: 0 | AF8: 1 | AG8: 1 | AH8: 0 | AI8: 0 | AJ8: 0 | AK8: 9 | AL8: 1 | AM8: 1 | AN8: 1 | AO8: 9 | AP8: 9
A9: CR7 | B9: 4 | C9: 0 | D9: 0 | E9: 0 | F9: 0 | G9: 3 | H9: 3 | I9: 3 | J9: 0 | K9: 0 | L9: 0 | M9: 0 | N9: 0 | O9: 9 | P9: 9 | Q9: 9 | R9: 9 | S9: 3 | T9: 3 | U9: 0 | V9: 0 | W9: 0 | X9: 0 | Y9: 0 | Z9: 0 | AA9: 1 | AB9: 1 | AC9: 0 | AD9: 0 | AE9: 0 | AF9: 3 | AG9: 3 | AH9: 0 | AI9: 0 | AJ9: 0 | AK9: 1 | AL9: 1 | AM9: 1 | AN9: 1 | AO9: 0 | AP9: 0
A10: CR8 | B10: 3 | C10: 1 | D10: 1 | E10: 0 | F10: 0 | G10: 3 | H10: 3 | I10: 1 | J10: 1 | K10: 1 | L10: 0 | M10: 0 | N10: 0 | O10: 3 | P10: 3 | Q10: 9 | R10: 9 | S10: 1 | T10: 1 | U10: 0 | V10: 0 | W10: 0 | X10: 0 | Y10: 0 | Z10: 0 | AA10: 1 | AB10: 1 | AC10: 0 | AD10: 0 | AE10: 0 | AF10: 3 | AG10: 3 | AH10: 0 | AI10: 0 | AJ10: 0 | AK10: 1 | AL10: 1 | AM10: 1 | AN10: 1 | AO10: 0 | AP10: 0
A11: CR9 | B11: 3 | C11: 1 | D11: 1 | E11: 0 | F11: 0 | G11: 1 | H11: 1 | I11: 0 | J11: 1 | K11: 1 | L11: 0 | M11: 0 | N11: 0 | O11: 3 | P11: 3 | Q11: 3 | R11: 3 | S11: 9 | T11: 9 | U11: 0 | V11: 0 | W11: 0 | X11: 0 | Y11: 0 | Z11: 0 | AA11: 1 | AB11: 1 | AC11: 0 | AD11: 0 | AE11: 0 | AF11: 3 | AG11: 3 | AH11: 0 | AI11: 0 | AJ11: 0 | AK11: 1 | AL11: 1 | AM11: 1 | AN11: 1 | AO11: 0 | AP11: 0
A12: CR10 | B12: 4 | C12: 1 | D12: 1 | E12: 1 | F12: 1 | G12: 1 | H12: 1 | I12: 1 | J12: 1 | K12: 1 | L12: 0 | M12: 0 | N12: 0 | O12: 0 | P12: 0 | Q12: 1 | R12: 1 | S12: 1 | T12: 1 | U12: 9 | V12: 9 | W12: 3 | X12: 3 | Y12: 3 | Z12: 3 | AA12: 1 | AB12: 1 | AC12: 0 | AD12: 0 | AE12: 0 | AF12: 1 | AG12: 1 | AH12: 0 | AI12: 0 | AJ12: 0 | AK12: 1 | AL12: 1 | AM12: 1 | AN12: 1 | AO12: 0 | AP12: 0
A13: CR11 | B13: 4 | C13: 1 | D13: 1 | E13: 1 | F13: 1 | G13: 1 | H13: 1 | I13: 1 | J13: 1 | K13: 1 | L13: 0 | M13: 0 | N13: 0 | O13: 0 | P13: 1 | Q13: 1 | R13: 1 | S13: 1 | T13: 3 | U13: 3 | V13: 9 | W13: 9 | X13: 3 | Y13: 3 | Z13: 1 | AA13: 1 | AB13: 0 | AC13: 0 | AD13: 0 | AE13: 0 | AF13: 1 | AG13: 1 | AH13: 0 | AI13: 0 | AJ13: 0 | AK13: 1 | AL13: 1 | AM13: 1 | AN13: 1 | AO13: 0 | AP13: 0
A14: CR12 | B14: 3 | C14: 1 | D14: 1 | E14: 0 | F14: 0 | G14: 1 | H14: 1 | I14: 1 | J14: 1 | K14: 1 | L14: 0 | M14: 0 | N14: 0 | O14: 0 | P14: 1 | Q14: 1 | R14: 1 | S14: 1 | T14: 3 | U14: 3 | V14: 3 | W14: 3 | X14: 9 | Y14: 9 | Z14: 1 | AA14: 1 | AB14: 0 | AC14: 0 | AD14: 0 | AE14: 0 | AF14: 1 | AG14: 1 | AH14: 0 | AI14: 0 | AJ14: 0 | AK14: 1 | AL14: 1 | AM14: 1 | AN14: 1 | AO14: 0 | AP14: 0
... A23: CR21 | B23: 4 | C23: 1 | D23: 1 | E23: 0 | F23: 0 | G23: 1 | H23: 1 | I23: 1 | J23: 1 | K23: 1 | L23: 0 | M23: 0 | N23: 0 | O23: 0 | P23: 1 | Q23: 1 | R23: 1 | S23: 1 | T23: 1 | U23: 1 | V23: 3 | W23: 3 | X23: 3 | Y23: 3 | Z23: 1 | AA23: 1 | AB23: 0 | AC23: 0 | AD23: 0 | AE23: 0 | AF23: 1 | AG23: 1 | AH23: 0 | AI23: 0 | AJ23: 0 | AK23: 0 | AL23: 1 | AM23: 1 | AN23: 9 | AO23: 9 | AP23: 3
A24: Raw | B24: Importance | C24: {=SUM($B$3:$B$23*C3:C23)} -> 136 | D24: {=SUM($B$3:$B$23*D3:D23)} -> 136 | E24: {=SUM($B$3:$B$23*E3:E23)} -> 98 | F24: {=SUM($B$3:$B$23*F3:F23)} -> 98 | G24: {=SUM($B$3:$B$23*G3:G23)} -> 121 | H24: {=SUM($B$3:$B$23*H3:H23)} -> 121 | I24: {=SUM($B$3:$B$23*I3:I23)} -> 84 | J24: {=SUM($B$3:$B$23*J3:J23)} -> 166 | ... AP24: {=SUM($B$3:$B$23*AP3:AP23)} -> 39
A25: % | C25: =C24/SUM($C$24:$AP$24) -> 0.032181732 | D25: =D24/SUM($C$24:$AP$24) -> 0.032181732 | E25: =E24/SUM($C$24:$AP$24) -> 0.023189778 | F25: =F24/SUM($C$24:$AP$24) -> 0.023189778 | G25: =G24/SUM($C$24:$AP$24) -> 0.028632276 | H25: =H24/SUM($C$24:$AP$24) -> 0.028632276 | I25: =I24/SUM($C$24:$AP$24) -> 0.019876952 | J25: =J24/SUM($C$24:$AP$24) -> 0.039280644 | ... AP25: =AP24/SUM($C$24:$AP$24) -> 0.009228585
A26: Rank | C26: =_xlfn.RANK.EQ(C24, $C$24:$AP$24) -> 10 | D26: =_xlfn.RANK.EQ(D24, $C$24:$AP$24) -> 10 | E26: =_xlfn.RANK.EQ(E24, $C$24:$AP$24) -> 20 | F26: =_xlfn.RANK.EQ(F24, $C$24:$AP$24) -> 20 | G26: =_xlfn.RANK.EQ(G24, $C$24:$AP$24) -> 16 | H26: =_xlfn.RANK.EQ(H24, $C$24:$AP$24) -> 16 | I26: =_xlfn.RANK.EQ(I24, $C$24:$AP$24) -> 27 | J26: =_xlfn.RANK.EQ(J24, $C$24:$AP$24) -> 5 | ... AP26: =_xlfn.RANK.EQ(AP24, $C$24:$AP$24) -> 38

Sheet Technical Assesment and ranges
D2: Competitor Assesment | H2: Product Requirement
B3: Technical Requirement | C3: Units | D3: Overall Range | E3: Battery-Powered | F3: Manual | G3: Solar-Powered | H3: Target Range | I3: Fallback Range | J3: References
B4: Water Transfer Rate | C4: L/min | D4: 1 – 35 | E4: 30 – 35 | F4: 1 – 15 | G4: 10 – 15 | H4: 50 – 60 | I4: 30 – 49 | J4: A.1, B2
B5: Time to Water Garden | C5: Minutes | D5: 15 – 60 | E5: 15 – 30 | F5: 30 – 60 | G5: 20 – 40 | H5: ≤15 | I5: 16 – 30 | J5: A.2
B6: Distribution Uniformity | C6: % | D6: 60% – 90% | E6: 80% – 90% | F6: 60% – 75% | G6: 75% – 85% | H6: 85% – 90% | I6: 75% – 84% | J6: A.10, B4
B7: Soil Moisture Variation | C7: % water | D7: ±5% – ±15% | E7: ±5% | F7: ±15% | G7: ±10% | H7: ±0% – ±5% | I7: ±5% – ±10% | J7: A.10, B4
B8: Manual Operations Count | C8: Count | D8: 1 – High | E8: 1 – 2 | F8: Continuous | G8: 1 – 2 | H8: 1 – 2 | I8: 3 – 4 | J8: B11, B12
B9: Operational Effort Time | C9: Minutes | D9: 1 – 60 | E9: 1 – 2 | F9: 30 – 60 | G9: 1 – 2 | H9: ≤2 | I9: 3 – 5 | J9: B11, B12
B10: Physical Exertion Level | C10: Borg Scale | D10: 6 – 15 | E10: 6 | F10: 13 – 15 | G10: 6 | H10: 6 – 9 | I10: 10 – 11 | J10: B12, B13
B11: Water Pressure at Delivery | C11: kPa | D11: 50 – 250 | E11: 200 – 250 | F11: 50 – 100 | G11: 100 – 150 | H11: 300 – 400 | I11: 200 – 299 | J11: A.3, B2
B12: Flow Rate per Method | C12: L/min | D12: 1 – 35 | E12: 30 – 35 | F12: 1 – 15 | G12: 10 – 15 | H12: 50 – 60 | I12: 30 – 49 | J12: A.1, A.4
B13: Flow Rate Consistency | C13: % variation | D13: ±5% – ±20% | E13: ±5% | F13: ±20% | G13: ±10% | H13: ±0% – ±5% | I13: ±5% – ±10% | J13: A.10, B4
B14: Performance at Varying Levels | C14: L/min and kPa | D14: Varies | E14: Consistent | F14: Decreases | G14: Moderate | H14: Consistent | I14: Minor decrease | J14: A.4, B2
B15: Minimum Operational Water Level | C15: Liters | D15: 5 – 20 | E15: 10 – 20 | F15: 5 – 10 | G15: 10 – 15 | H15: ≤100 | I15: 101 – 200 | J15: A.7, B5
B16: Learning Time for New Users | C16: Minutes | D16: 5 – 20 | E16: 5 – 10 | F16: 5 – 15 | G16: 10 – 20 | H16: ≤5 | I16: 6 – 10 | J16: B11, B13
B17: User Error Rate | C17: Errors/op cycle | D17: 0.01-0.05 | E17: Low (0.01) | F17: Moderate (0.05) | G17: Low (0.02) | H17: ≤0.01 | I17: 0.011 – 0.02 | J17: B12, B14
B18: Control Interface Count | C18: Count | D18: 1 – 3 | E18: 1 – 2 | F18: 1 | G18: 1 – 3 | H18: 1 – 2 | I18: 2-5 | J18: B11, B14
B19: Operation Initiation Time | C19: Seconds | D19: Immediate – 20 | E19: 5 – 10 | F19: Immediate | G19: 10 – 20 | H19: ≤5 | I19: 6 – 10 | J19: B11, B13
B20: Instruction Steps Count | C20: Count | D20: 2 – 6 | E20: 3 – 5 | F20: 2 – 4 | G20: 4 – 6 | H20: ≤3 | I20: 4 – 5 | J20: B11, B14
B21: Instruction Clarity Rating | C21: Likert scale | D21: 4 – 5 | E21: 4 – 5 | F21: 4 – 5 | G21: 4 – 5 | H21: 4-5 | I21: 2-4 | J21: B11, B13
B22: Maintenance Frequency | C22: Times per year | D22: 1 – 4 | E22: 2 – 4 | F22: 1 – 2 | G22: 2 – 3 | H22: 1-2 | I22: 2-6 | J22: A.9
B23: Maintenance Duration | C23: Minutes | D23: 10 – 30 | E23: 15 – 30 | F23: 10 – 20 | G23: 20 – 30 | H23: ≤30 | I23: 31 – 60 | J23: A.9
B24: Expected Lifespan | C24: Years | D24: 3 – 10 | E24: 3 – 5 | F24: 5 – 10 | G24: 3 – 7 | H24: 5 – 10 | I24: 3 – 4 | J24: A.9
B25: Warranty Period | C25: Years | D25: 1 – 3 | E25: 2 – 3 | F25: 1 – 2 | G25: 1 – 3 | H25: 3+ | I25: 0-3 | J25: N/A
B26: Troubleshooting Time | C26: Minutes | D26: 10 – 40 | E26: 15 – 30 | F26: 10 – 20 | G26: 20 – 40 | H26: ≤10 | I26: 11 – 20 | J26: B12, B14
B27: Diagnostic Tools Availability | C27: Yes/No | D27: Yes/No | E27: Yes | F27: No | G27: Yes | H27: Yes | I27: No | J27: B12, B14
B28: Eco-Friendly Materials % | C28: % | D28: 60% – 80% | E28: 60% – 80% | F28: 60% – 80% | G28: 60% – 80% | H28: 80% – 100% | I28: 60% – 79% | J28: B10
B29: Potable Water Savings | C29: Liters/month | D29: 1,000 – 3,000 | E29: 1,000 – 3,000 | F29: 1,000 – 3,000 | G29: 1,000 – 3,000 | H29: ≥3,000 | I29: 2,000 – 2,999 | J29: A.6, B5
B30: Rainwater Utilization Rate | C30: % | D30: 80% – 95% | E30: 80% – 95% | F30: 80% – 95% | G30: 80% – 95% | H30: 90% – 100% | I30: 80% – 89% | J30: A.7, B5
... B34: Cost per Garden Area | C34: $/m² | D34: $1 – $5 | E34: $1 – $5 | F34: $1 – $5 | G34: $1 – $5 | H34: $0 – $5 | I34: $6 – $10 | J34: A.9
B35: Annual Operational Cost | C35: $/year | D35: $0 – $20 | E35: $10 – $20 | F35: 0 | G35: $0 – $10 | H35: ≤50 | I35: 51 – 100 | J35: A.5
B36: Total Cost of Ownership | C36: $ | D36: $30 – $350 | E36: $200 – $350 | F36: $30 – $150 | G36: $170 – $350 | H36: ≤1,500 | I36: 1,501 – 2,000 | J36: A.9
B37: Cost per Year of Lifespan | C37: $/year | D37: $6 – $70 | E37: $40 – $70 | F37: $6 – $30 | G37: $34 – $70 | H37: ≤150 | I37: 151 – 200 | J37: A.9
B38: Water Use Efficiency | C38: % | D38: 70% – 90% | E38: 80% – 90% | F38: 70% – 80% | G38: 75% – 85% | H38: 90% – 100% | I38: 80% – 89% | J38: A.10, B4
B39: Standards Compliance Count | C39: Count | D39: 1 – 3 | E39: 2 – 3 | F39: 1 – 2 | G39: 2 – 3 | H39: All standards | I39: All critical standards | J39: B6
B40: Certification Status | C40: Yes/No | D40: Yes | E40: Yes | F40: Yes | G40: Yes | H40: Yes | I40: Yes | J40: B6
B41: Hazard Count | C41: Count | D41: 1 – 2 | E41: 1 – 2 | F41: 1 | G41: 1 – 2 | H41: 0 – 1 | I41: 1-3 | J41: A.9
B42: Risk Assessment Score | C42: Low/High | D42: Low | E42: Low | F42: Low | G42: Low | H42: Low | I42: Moderate | J42: A.9
B43: Operational Temperature Range | C43: °C | D43: 0°C – 40°C | E43: 0°C – 40°C | F43: 0°C – 40°C | G43: 0°C – 40°C | H43: -5 to 40 | I43: 0 to 35 | J43: A.11, B10

Sheet Tech Req
A1: CR # | B1: Metric | C1: Unit
A2: 1 | B2: Water Transfer Rate | C2: L/min
A3: 2 | B3: Time to Water Garden | C3: Minutes
A4: 3 | B4: Distribution Uniformity | C4: %
A5: 4 | B5: Soil Moisture Variation | C5: % water content
A6: 5 | B6: Manual Operations Count | C6: Count
A7: 6 | B7: Operational Effort Time | C7: Minutes
A8: 7 | B8: Physical Exertion Level | C8: Borg Scale units (6–20)
A9: 8 | B9: Water Pressure at Delivery | C9: kPa
A10: 9 | B10: Flow Rate per Method | C10: L/min
A11: 10 | B11: Flow Rate Consistency | C11: % variation
A12: 11 | B12: Performance at Varying Levels | C12: L/min and kPa
A13: 12 | B13: Minimum Operational Water Level | C13: Liters
... A41: 40 | B41: Operational Temperature Range | C41: °C

Sheet TR-TR
A1: 1 | B1: o
A2: 2 | B2: ++ | C2: o
A3: 3 | B3: + | C3: + | D3: o
A4: 4 | B4: o | C4: o | D4: ++ | E4: o
A5: 5 | B5: - | C5: - | D5: o | E5: - | F5: o
A6: 6 | B6: - | C6: - | D6: o | E6: - | F6: ++ | G6: o
A7: 7 | B7: - | C7: - | D7: o | E7: - | F7: ++ | G7: ++ | H7: o
A8: 8 | B8: + | C8: + | D8: + | E8: o | F8: o | G8: o | H8: o | I8: o
A9: 9 | B9: ++ | C9: ++ | D9: + | E9: o | F9: - | G9: - | H9: - | I9: ++ | J9: o
A10: 10 | B10: + | C10: + | D10: ++ | E10: o | F10: - | G10: - | H10: - | I10: + | J10: ++ | K10: o
A11: 11 | B11: ++ | C11: ++ | D11: + | E11: o | F11: - | G11: - | H11: - | I11: ++ | J11: ++ | K11: ++ | L11: o
A12: 12 | B12: o | C12: o | D12: o | E12: o | F12: o | G12: o | H12: o | I12: o | J12: o | K12: o | L12: o | M12: o
A13: 13 | B13: o | C13: o | D13: o | E13: o | F13: + | G13: + | H13: o | I13: o | J13: o | K13: o | L13: + | M13: o | N13: o
A14: 14 | B14: - | C14: - | D14: o | E14: - | F14: + | G14: + | H14: + | I14: - | J14: - | K14: - | L14: - | M14: o | N14: ++ | O14: o
A15: 15 | B15: - | C15: - | D15: o | E15: o | F15: + | G15: + | H15: + | I15: - | J15: - | K15: - | L15: - | M15: o | N15: + | O15: + | P15: o
A16: 16 | B16: - | C16: - | D16: o | E16: o | F16: + | G16: + | H16: o | I16: o | J16: o | K16: o | L16: - | M16: o | N16: o | O16: + | P16: + | Q16: o
A17: 17 | B17: - | C17: - | D17: o | E17: o | F17: + | G17: + | H17: o | I17: - | J17: - | K17: - | L17: - | M17: o | N17: + | O17: + | P17: + | Q17: + | R17: o
A18: 18 | B18: + | C18: + | D18: + | E18: + | F18: + | G18: + | H18: o | I18: + | J18: + | K18: + | L18: + | M18: o | N18: - | O18: - | P18: + | Q18: - | R18: - | S18: o
A19: 19 | B19: - | C19: - | D19: o | E19: o | F19: - | G19: - | H19: o | I19: - | J19: - | K19: o | L19: - | M19: o | N19: o | O19: o | P19: - | Q19: o | R19: o | S19: + | T19: o
A20: 20 | B20: - | C20: o | D20: o | E20: o | F20: - | G20: - | H20: o | I20: - | J20: - | K20: o | L20: - | M20: o | N20: o | O20: o | P20: - | Q20: o | R20: o | S20: + | T20: + | U20: o
A21: 21 | B21: - | C21: o | D21: o | E21: o | F21: - | G21: - | H21: o | I21: - | J21: - | K21: o | L21: - | M21: o | N21: o | O21: - | P21: - | Q21: o | R21: o | S21: + | T21: - | U21: - | V21: o
A22: 22 | B22: o | C22: o | D22: o | E22: o | F22: o | G22: o | H22: o | I22: o | J22: o | K22: o | L22: o | M22: o | N22: o | O22: o | P22: o | Q22: o | R22: o | S22: o | T22: o | U22: o | V22: + | W22: o
A23: 23 | B23: - | C23: o | D23: o | E23: o | F23: - | G23: - | H23: o | I23: - | J23: - | K23: - | L23: - | M23: o | N23: o | O23: - | P23: - | Q23: o | R23: o | S23: + | T23: - | U23: - | V23: - | W23: o | X23: o
A24: 24 | B24: + | C24: o | D24: + | E24: + | F24: + | G24: + | H24: o | I24: + | J24: + | K24: + | L24: + | M24: o | N24: o | O24: - | P24: + | Q24: o | R24: o | S24: + | T24: + | U24: + | V24: + | W24: o | X24: ++ | Y24: o
A25: 25 | B25: o | C25: o | D25: o | E25: o | F25: o | G25: o | H25: o | I25: o | J25: o | K25: o | L25: o | M25: o | N25: o | O25: o | P25: o | Q25: o | R25: o | S25: o | T25: o | U25: o | V25: + | W25: o | X25: o | Y25: o | Z25: o
A26: 26 | B26: + | C26: + | D26: + | E26: + | F26: - | G26: - | H26: o | I26: + | J26: + | K26: + | L26: + | M26: o | N26: o | O26: - | P26: o | Q26: o | R26: o | S26: + | T26: o | U26: o | V26: o | W26: o | X26: o | Y26: + | Z26: + | AA26: o
A27: 27 | B27: + | C27: + | D27: + | E27: + | F27: - | G27: - | H27: o | I27: + | J27: + | K27: + | L27: + | M27: o | N27: o | O27: - | P27: o | Q27: o | R27: o | S27: + | T27: o | U27: o | V27: o | W27: o | X27: o | Y27: + | Z27: + | AA27: ++ | AB27: o
A28: 28 | B28: + | C28: + | D28: + | E28: + | F28: o | G28: o | H28: o | I28: + | J28: + | K28: + | L28: + | M28: o | N28: o | O28: o | P28: o | Q28: o | R28: o | S28: o | T28: + | U28: + | V28: + | W28: o | X28: + | Y28: + | Z28: o | AA28: + | AB28: + | AC28: o
A29: 29 | B29: o | C29: o | D29: o | E29: o | F29: o | G29: o | H29: o | I29: o | J29: o | K29: o | L29: o | M29: o | N29: o | O29: o | P29: o | Q29: o | R29: o | S29: o | T29: o | U29: o | V29: o | W29: o | X29: o | Y29: o | Z29: o | AA29: o | AB29: o | AC29: o | AD29: o
A30: 30 | B30: - | C30: - | D30: - | E30: - | F30: o | G30: o | H30: o | I30: - | J30: - | K30: - | L30: - | M30: o | N30: o | O30: o | P30: - | Q30: o | R30: o | S30: o | T30: o | U30: o | V30: + | W30: + | X30: o | Y30: + | Z30: + | AA30: o | AB30: o | AC30: o | AD30: + | AE30: o
A31: 31 | B31: - | C31: - | D31: - | E31: - | F31: o | G31: o | H31: o | I31: - | J31: - | K31: - | L31: - | M31: o | N31: o | O31: o | P31: - | Q31: o | R31: o | S31: o | T31: o | U31: o | V31: + | W31: + | X31: o | Y31: + | Z31: + | AA31: o | AB31: o | AC31: o | AD31: + | AE31: + | AF31: o
A32: 32 | B32: - | C32: o | D32: o | E32: o | F32: + | G32: + | H32: o | I32: - | J32: - | K32: o | L32: - | M32: o | N32: o | O32: + | P32: + | Q32: o | R32: o | S32: - | T32: + | U32: + | V32: - | W32: o | X32: + | Y32: - | Z32: o | AA32: - | AB32: - | AC32: o | AD32: o | AE32: o | AF32: o | AG32: o
A33: 33 | B33: - | C33: - | D33: - | E33: - | F33: + | G33: + | H33: o | I33: - | J33: - | K33: - | L33: - | M33: o | N33: o | O33: + | P33: + | Q33: o | R33: o | S33: - | T33: + | U33: + | V33: - | W33: + | X33: + | Y33: + | Z33: + | AA33: - | AB33: - | AC33: o | AD33: o | AE33: + | AF33: + | AG33: + | AH33: o
A34: 34 | B34: - | C34: o | D34: o | E34: o | F34: + | G34: + | H34: o | I34: - | J34: - | K34: o | L34: - | M34: o | N34: o | O34: + | P34: + | Q34: o | R34: o | S34: - | T34: + | U34: + | V34: - | W34: o | X34: + | Y34: - | Z34: + | AA34: - | AB34: - | AC34: o | AD34: o | AE34: + | AF34: + | AG34: + | AH34: + | AI34: o
A35: 35 | B35: ++ | C35: + | D35: ++ | E35: ++ | F35: - | G35: - | H35: o | I35: + | J35: ++ | K35: ++ | L35: + | M35: o | N35: o | O35: - | P35: o | Q35: o | R35: o | S35: + | T35: o | U35: o | V35: o | W35: o | X35: - | Y35: + | Z35: o | AA35: ++ | AB35: ++ | AC35: + | AD35: o | AE35: o | AF35: o | AG35: - | AH35: - | AI35: - | AJ35: o
A36: 36 | B36: + | C36: + | D36: + | E36: + | F36: o | G36: o | H36: o | I36: + | J36: + | K36: + | L36: + | M36: o | N36: o | O36: o | P36: o | Q36: o | R36: o | S36: o | T36: o | U36: o | V36: + | W36: + | X36: o | Y36: + | Z36: + | AA36: + | AB36: + | AC36: + | AD36: + | AE36: o | AF36: o | AG36: o | AH36: o | AI36: o | AJ36: + | AK36: o
A37: 37 | B37: + | C37: + | D37: + | E37: + | F37: o | G37: o | H37: o | I37: + | J37: + | K37: + | L37: + | M37: o | N37: o | O37: o | P37: o | Q37: o | R37: o | S37: o | T37: o | U37: o | V37: + | W37: + | X37: o | Y37: + | Z37: + | AA37: + | AB37: + | AC37: + | AD37: + | AE37: o | AF37: o | AG37: o | AH37: o | AI37: o | AJ37: + | AK37: + | AL37: o
A38: 38 | B38: + | C38: o | D38: o | E38: o | F38: + | G38: + | H38: o | I38: + | J38: + | K38: o | L38: + | M38: o | N38: o | O38: + | P38: + | Q38: o | R38: o | S38: - | T38: + | U38: + | V38: + | W38: o | X38: + | Y38: - | Z38: o | AA38: o | AB38: o | AC38: - | AD38: o | AE38: o | AF38: o | AG38: o | AH38: o | AI38: o | AJ38: - | AK38: - | AL38: - | AM38: o
A39: 39 | B39: + | C39: o | D39: o | E39: o | F39: + | G39: + | H39: o | I39: + | J39: + | K39: o | L39: + | M39: o | N39: o | O39: + | P39: + | Q39: o | R39: o | S39: - | T39: + | U39: + | V39: + | W39: o | X39: + | Y39: - | Z39: o | AA39: o | AB39: o | AC39: - | AD39: o | AE39: o | AF39: o | AG39: o | AH39: o | AI39: o | AJ39: - | AK39: - | AL39: - | AM39: + | AN39: o
A40: 40 | B40: o | C40: o | D40: o | E40: o | F40: o | G40: o | H40: o | I40: o | J40: o | K40: o | L40: o | M40: o | N40: o | O40: o | P40: o | Q40: o | R40: o | S40: o | T40: + | U40: + | V40: + | W40: o | X40: + | Y40: o | Z40: o | AA40: o | AB40: o | AC40: o | AD40: o | AE40: o | AF40: o | AG40: + | AH40: + | AI40: + | AJ40: o | AK40: + | AL40: + | AM40: + | AN40: + | AO40: o
...

Sheet Metrics_Voting
A1: EMCH 427 Facilities Rain Barrel | C1: Ranking | D1: Name | E1: Rank | F1: Metrics | G1: Units | H1: Name | I1: Rank | J1: Metrics | K1: Units | L1: Name | M1: Rank | N1: Metrics | O1: Units | P1: Name | Q1: Rank | R1: Metrics | S1: Units
A2: Category: | B2: Operational Efficiency
A3: 1 | B3: The system should enable quick and efficient water transfer from the tank to the garden. | C3: =AVERAGE(E3,I3,M3,Q3) -> 4 | D3: JVAUGHT | E3: 5 | F3: Time to transfer 2 gallons | G3: seconds | H3: WWENZEL | I3: 5 | J3: Average flow rate during transfer | K3: GPM | L3: TBHARMON | M3: 3 | N3: Energy consumption per 2 gallons transferred | O3: kWH | P3: PRESSTON | Q3: 3 | R3: Maximum throughput capacity of the system | S3: GPH
A4: 2 | B4: The system should provide consistent and reliable water distribution across the entire garden area. | C4: =AVERAGE(E4,I4,M4,Q4) -> 3.25 | D4: JVAUGHT | E4: 2 | F4: Distribution Uniformity (DU) coefficient | G4: Percentage | H4: WWENZEL | I4: 3 | J4: Variance in water application rates between zones | K4: GPM | L4: TBHARMON | M4: 3 | N4: Number of dry or overwatered spots detected | O4: Count | P4: PRESSTON | Q4: 5 | R4: System reliability (uptime percentage) | S4: Percentage
A5: 3 | B5: The system should minimize manual labor and physical effort required to operate. | C5: =AVERAGE(E5,I5,M5,Q5) -> 4 | D5: JVAUGHT | E5: 5 | F5: Physical force required to operate controls | G5: lbf | H5: WWENZEL | I5: 2 | J5: Number of manual operations per watering cycle | K5: Count | L5: TBHARMON | M5: 5 | N5: Total operator time per watering session | O5: Minutes | P5: PRESSTON | Q5: 4 | R5: Operator perceived exertion rating | S5: Borg RPE scale (6-20)
A6: Category: | B6: Pressure and Flow | D6: Ashmore, Makayla
A7: 4 | B7: The system should provide sufficient water pressure for effective delivery. | C7: =AVERAGE(E7,I7,M7,Q7) -> 3.75 | D7: JVAUGHT | E7: 5 | F7: Operating pressure at system output | G7: psi | H7: WWENZEL | I7: 3 | J7: Pressure loss from tank to farthest point | K7: psi | L7: TBHARMON | M7: 4 | N7: Minimum pressure required for optimal operation | O7: psi | P7: PRESSTON | Q7: 3 | R7: Pressure fluctuation during operation | S7: psi variance
A8: 5 | B8: The system should maintain adequate flow rate for different watering methods. | C8: =AVERAGE(E8,I8,M8,Q8) -> 3 | D8: JVAUGHT | E8: 5 | F8: Flow rate achievable for drip irrigation | G8: GPH | H8: WWENZEL | I8: 1 | J8: Flow rate achievable for sprinkler systems | K8: gpm | L8: TBHARMON | M8: 2 | N8: Adjustability range of flow rates | O8: min to max gpm | P8: PRESSTON | Q8: 4 | R8: Flow rate consistency over time | S8: Standard deviation in gpm
A9: 6 | B9: The system should function efficiently with varying water levels in the tank. | C9: =AVERAGE(E9,I9,M9,Q9) -> 3.25 | D9: JVAUGHT | E9: 2 | F9: System efficiency at full tank level | G9: % efficiency | H9: WWENZEL | I9: 4 | J9: System efficiency at half tank level | K9: % Efficiency | L9: TBHARMON | M9: 3 | N9: Minimum operational water level required | O9: gallons | P9: PRESSTON | Q9: 4 | R9: Variation in flow rate across different tank levels | S9: Percentage variation
A10: Category: | B10: Usability | D10: Broadwell, Rose
A11: 7 | B11: The system should be easy to operate for users without technical expertise. | C11: =AVERAGE(E11,I11,M11,Q11) -> 3.5 | D11: JVAUGHT | E11: 5 | F11: Required training time for new users | G11: hours | H11: WWENZEL | I11: 3 | J11: User error rate during operation | K11: error/100 ops | L11: TBHARMON | M11: 3 | N11: User satisfaction rating on ease of use | O11: likert scale | P11: PRESSTON | Q11: 3 | R11: Number of steps to complete basic operation | S11: Count
A12: 8 | B12: The system should have straightforward controls for starting, stopping, and adjusting as needed. | C12: =AVERAGE(E12,I12,M12,Q12) -> 1.5 | D12: JVAUGHT | E12: 1 | F12: Number of control interfaces | G12: count | H12: WWENZEL | I12: 2 | J12: Average time to start or stop the system | K12: seconds | L12: TBHARMON | M12: 1 | N12: Clarity of control labeling | O12: likert scale | P12: PRESSTON | Q12: 2 | R12: Accessibility compliance (e.g., ADA standards) | S12: Yes/No
A13: 9 | B13: The system should provide clear instructions and minimize operational steps. | C13: =AVERAGE(E13,I13,M13,Q13) -> 2 | D13: JVAUGHT | E13: 1 | F13: Length of instruction manual | G13: pages | H13: WWENZEL | I13: 2 | J13: Reading level required to understand instructions | K13: grade level | L13: TBHARMON | M13: 2 | N13: Number of operational steps for basic use | O13: count | P13: PRESSTON | Q13: 3 | R13: User comprehension rate after first read | S13: Percentage
A14: Category: | B14: Maintenance
A15: 10 | B15: The system should require minimal maintenance for reliable operation. | C15: =AVERAGE(E15,I15,M15,Q15) -> 3.75 | D15: JVAUGHT | E15: 3 | F15: Scheduled maintenance frequency | G15: # per year | H15: WWENZEL | I15: 3 | J15: Mean time between failures (MTBF) | K15: hours or months | L15: TBHARMON | M15: 4 | N15: Average maintenance duration per session | O15: Hours | P15: PRESSTON | Q15: 5 | R15: Maintenance cost per year | S15: Dollars
A16: 11 | B16: The system should be durable and resistant to wear and tear under normal conditions. | C16: =AVERAGE(E16,I16,M16,Q16) -> 3.25 | D16: JVAUGHT | E16: 2 | F16: Expected lifespan of components | G16: years | H16: WWENZEL | I16: 4 | J16: Material wear rate under standard conditions | K16: % wear per yr | L16: TBHARMON | M16: 3 | N16: # of components needing replacement per yr | O16: Count | P16: PRESSTON | Q16: 4 | R16: component warranty period | S16: Years
A17: 12 | B17: The system should allow easy troubleshooting of common issues. | C17: =AVERAGE(E17,I17,M17,Q17) -> 3.25 | D17: JVAUGHT | E17: 1 | F17: Time to diagnose a common issue | G17: minutes | H17: WWENZEL | I17: 5 | J17: Availability of troubleshooting guide | K17: yes/no | L17: TBHARMON | M17: 3 | N17: User success rate in resolving issues independently | O17: Percentage | P17: PRESSTON | Q17: 4 | R17: Number of common issues covered in manual | S17: Count
A18: Category: | B18: Environmental Impact
A19: 13 | B19: The system should minimize environmental impact and align with sustainability goals. | C19: =AVERAGE(E19,I19,M19,Q19) -> 3.25 | D19: JVAUGHT | E19: 1 | F19: Carbon footprint during operation | G19: CO₂/yr | H19: WWENZEL | I19: 3 | J19: Percentage of recyclable materials used | K19: Percentage | L19: TBHARMON | M19: 4 | N19: Energy consumption per year | O19: kWh | P19: PRESSTON | Q19: 5 | R19: Compliance with environmental standards (LEED) | S19: Yes/No
A20: 14 | B20: The system should be compatible with rainwater harvesting practices. | C20: =AVERAGE(E20,I20,M20,Q20) -> 2.75 | D20: JVAUGHT | E20: 3 | F20: Compatibility with existing rainwater tanks | G20: Yes/No | H20: WWENZEL | I20: 1 | J20: Adaptability to different rainwater sources | K20: # of compatible source | L20: TBHARMON | M20: 3 | N20: Percentage of water supplied from roof-water | O20: Percentage | P20: PRESSTON | Q20: 4 | R20: Ease of integration with harvesting systems | S20: Likert Scale
A21: 15 | B21: The system should be designed to minimize noise pollution. | C21: =AVERAGE(E21,I21,M21,Q21) -> 3.5 | D21: JVAUGHT | E21: 5 | F21: Operating noise level at 1-meter distance | G21: Decibels | H21: WWENZEL | I21: 2 | J21: Noise level compared to acceptable standards | K21: Decibels Difference | L21: TBHARMON | M21: 3 | N21: User annoyance rating due to noise | O21: Likert scale | P21: PRESSTON | Q21: 4 | R21: Time during which noise exceeds thresholds | S21: Min per day
A22: Category: | B22: Cost and Budgetary
A23: 16 | B23: The system should be cost-effective to implement within the given budget. | C23: =AVERAGE(E23,I23,M23,Q23) -> 3.75 | D23: JVAUGHT | E23: 3 | F23: Total initial cost | G23: Dollars | H23: WWENZEL | I23: 2 | J23: Percentage of budget utilized | K23: Percentage | L23: TBHARMON | M23: 5 | N23: Cost savings compared to alternative solutions | O23: Dollars | P23: PRESSTON | Q23: 5 | R23: Return on investment period | S23: Years
A24: 17 | B24: The system should have low operational and maintenance costs over its lifetime. | C24: =AVERAGE(E24,I24,M24,Q24) -> 3.75 | D24: JVAUGHT | E24: 2 | F24: Annual operational cost | G24: Dollars/year | H24: WWENZEL | I24: 4 | J24: Annual maintenance cost | K24: Dollars/yr | L24: TBHARMON | M24: 4 | N24: Total cost of ownership over expected lifespan | O24: Dollars | P24: PRESSTON | Q24: 5 | R24: Cost per gallon of water delivered | S24: Dollars per gallon
A25: 18 | B25: The system should provide good value through durability and efficiency. | C25: =AVERAGE(E25,I25,M25,Q25) -> 2.75 | D25: JVAUGHT | E25: 1 | F25: Cost per year over lifespan | G25: Dollars/year | H25: WWENZEL | I25: 3 | J25: Efficiency rating of system components | K25: Percentage | L25: TBHARMON | M25: 3 | N25: Maintenance cost savings due to durability | O25: Dollars/yr | P25: PRESSTON | Q25: 4 | R25: User satisfaction rating on value | S25: Likert scale
A26: Category: | B26: Safety and Compliance
A27: 19 | B27: The system should comply with all relevant safety standards and regulations. | C27: =AVERAGE(E27,I27,M27,Q27) -> 3 | D27: JVAUGHT | E27: 2 | F27: Number of applicable standards met | G27: Count | H27: WWENZEL | I27: 3 | J27: Compliance certification status | K27: Yes/No | L27: TBHARMON | M27: 3 | N27: Number of non-compliance issues identified | O27: Count | P27: PRESSTON | Q27: 4 | R27: Time to achieve full compliance | S27: Months
A28: 20 | B28: The system should not pose any risks to pedestrians or garden users. | C28: =AVERAGE(E28,I28,M28,Q28) -> 2.75 | D28: JVAUGHT | E28: 3 | F28: Number of potential hazards identified | G28: Count | H28: WWENZEL | I28: 3 | J28: Safety incident rate during operation | K28: Incidents per yr | L28: TBHARMON | M28: 2 | N28: Compliance with safety guidelines (e.g., OSHA) | O28: yes/no | P28: PRESSTON | Q28: 3 | R28: User perception of safety | S28: Likert Scale
A29: 21 | B29: The system should be safe to operate under various weather conditions. | C29: =AVERAGE(E29,I29,M29,Q29) -> 3.75 | D29: JVAUGHT | E29: 4 | F29: Operational reliability in adverse weather | G29: % uptime | H29: WWENZEL | I29: 3 | J29: Temperature range for safe operation | K29: Degrees Fahrenheit | L29: TBHARMON | M29: 4 | N29: Weatherproof rating of system components | O29: IP Rating | P29: PRESSTON | Q29: 4 | R29: Number of weather-related malfunctions per year | S29: Count
A31: Find the cells where your name appears (4 person per need)
A32: Indicate the Need's importance (5=extremely important, 1=minimally important)
A33: Identify the best metric(s) to assess each need.
A34: If you think there are multiple metrics, list each

Sheet Customer_Requirements
A1: Customer Req ID | B1: Customer Requirement | C1: Ranking
A2: CR1 | B2: The system should enable quick and efficient water transfer from the tank to the garden. | C2: =Metrics_Voting!C3 -> 4
A3: CR2 | B3: The system should provide consistent and reliable water distribution across the entire garden area. | C3: =Metrics_Voting!C4 -> 3.25
A4: CR3 | B4: The system should minimize manual labor and physical effort required to operate. | C4: =Metrics_Voting!C5 -> 4
A5: CR4 | B5: The system should provide sufficient water pressure for effective delivery. | C5: =Metrics_Voting!C7 -> 3.75
A6: CR5 | B6: The system should maintain adequate flow rate for different watering methods. | C6: =Metrics_Voting!C8 -> 3
A7: CR6 | B7: The system should function efficiently with varying water levels in the tank. | C7: =Metrics_Voting!C9 -> 3.25
A8: CR7 | B8: The system should be easy to operate for users without technical expertise. | C8: =Metrics_Voting!C11 -> 3.5
A9: CR8 | B9: The system should have straightforward controls for starting, stopping, and adjusting as needed. | C9: =Metrics_Voting!C12 -> 1.5
A10: CR9 | B10: The system should provide clear instructions and minimize operational steps. | C10: =Metrics_Voting!C13 -> 2
A11: CR10 | B11: The system should require minimal maintenance for reliable operation. | C11: =Metrics_Voting!C15 -> 3.75
A12: CR11 | B12: The system should be durable and resistant to wear and tear under normal conditions. | C12: =Metrics_Voting!C16 -> 3.25
A13: CR12 | B13: The system should allow easy troubleshooting of common issues. | C13: =Metrics_Voting!C17 -> 3.25
A14: CR13 | B14: The system should minimize environmental impact and align with sustainability goals. | C14: =Metrics_Voting!C19 -> 3.25
A15: CR14 | B15: The system should be compatible with rainwater harvesting practices. | C15: =Metrics_Voting!C20 -> 2.75
A16: CR15 | B16: The system should be designed to minimize noise pollution. | C16: =Metrics_Voting!C21 -> 3.5
A17: CR16 | B17: The system should be cost-effective to implement within the given budget. | C17: =Metrics_Voting!C23 -> 3.75
A18: CR17 | B18: The system should have low operational and maintenance costs over its lifetime. | C18: =Metrics_Voting!C24 -> 3.75
A19: CR18 | B19: The system should provide good value through durability and efficiency. | C19: =Metrics_Voting!C25 -> 2.75
A20: CR19 | B20: The system should comply with all relevant safety standards and regulations. | C20: =Metrics_Voting!C27 -> 3
A21: CR20 | B21: The system should not pose any risks to pedestrians or garden users. | C21: =Metrics_Voting!C28 -> 2.75
A22: CR21 | B22: The system should be safe to operate under various weather conditions. | C22: =Metrics_Voting!C29 -> 3.75

Sheet Pretty_CR
A1: Customer Requirement | B1: ID | C1: Requirement | D1: Units
A2: The system should enable quick and efficient water transfer from the tank to the garden. | B2: TR1 | C2: Time to transfer 2 gallons | D2: seconds
B3: TR2 | C3: Average flow rate during transfer | D3: GPM
B4: TR3 | C4: Energy consumption per 2 gallons transferred | D4: kWH
B5: TR4 | C5: Maximum throughput capacity of the system | D5: GPH
A6: The system should provide consistent and reliable water distribution across the entire garden area. | B6: TR5 | C6: Distribution Uniformity (DU) coefficient | D6: Percentage
B7: TR6 | C7: Variance in water application rates between zones | D7: GPM
B8: TR7 | C8: Number of dry or overwatered spots detected | D8: Count
B9: TR8 | C9: System reliability (uptime percentage) | D9: Percentage
A10: The system should minimize manual labor and physical effort required to operate. | B10: TR9 | C10: Physical force required to operate controls | D10: lbf
B11: TR10 | C11: Number of manual operations per watering cycle | D11: Count
B12: TR11 | C12: Total operator time per watering session | D12: Minutes
B13: TR12 | C13: Operator perceived exertion rating | D13: Borg RPE scale (6-20)
A14: The system should provide sufficient water pressure for effective delivery. | B14: TR13 | C14: Operating pressure at system output | D14: psi
B15: TR14 | C15: Pressure loss from tank to farthest point | D15: psi
B16: TR15 | C16: Minimum pressure required for optimal operation | D16: psi
B17: TR16 | C17: Pressure fluctuation during operation | D17: psi variance
A18: The system should maintain adequate flow rate for different watering methods. | B18: TR17 | C18: Flow rate achievable for drip irrigation | D18: GPH
B19: TR18 | C19: Flow rate achievable for sprinkler systems | D19: gpm
B20: TR19 | C20: Adjustability range of flow rates | D20: min to max gpm
B21: TR20 | C21: Flow rate consistency over time | D21: Standard deviation in gpm
A22: The system should function efficiently with varying water levels in the tank. | B22: TR21 | C22: System efficiency at full tank level | D22: % efficiency
B23: TR22 | C23: System efficiency at half tank level | D23: % Efficiency
B24: TR23 | C24: Minimum operational water level required | D24: gallons
B25: TR24 | C25: Variation in flow rate across different tank levels | D25: Percentage variation
A26: The system should be easy to operate for users without technical expertise. | B26: TR25 | C26: Required training time for new users | D26: hours
B27: TR26 | C27: User error rate during operation | D27: error/100 ops
B28: TR27 | C28: User satisfaction rating on ease of use | D28: likert scale
B29: TR28 | C29: Number of steps to complete basic operation | D29: Count
A30: The system should have straightforward controls for starting, stopping, and adjusting as needed. | B30: TR29 | C30: Number of control interfaces | D30: count
B31: TR30 | C31: Average time to start or stop the system | D31: seconds
B32: TR31 | C32: Clarity of control labeling | D32: likert scale
B33: TR32 | C33: Accessibility compliance (e.g., ADA standards) | D33: Yes/No
A34: The system should provide clear instructions and minimize operational steps. | B34: TR33 | C34: Length of instruction manual | D34: pages
B35: TR34 | C35: Reading level required to understand instructions | D35: grade level
B36: TR35 | C36: Number of operational steps for basic use | D36: count
B37: TR36 | C37: User comprehension rate after first read | D37: Percentage
A38: The system should require minimal maintenance for reliable operation. | B38: TR37 | C38: Scheduled maintenance frequency | D38: # per year
B39: TR38 | C39: Mean time between failures (MTBF) | D39: hours or months
B40: TR39 | C40: Average maintenance duration per session | D40: Hours
...

Sheet Technical_Requirements
A1: Tech Requirement ID | B1: Requirement | C1: Units
A2: TR1 | B2: Time to transfer 2 gallons | C2: seconds
A3: TR2 | B3: Average flow rate during transfer | C3: GPM
A4: TR3 | B4: Energy consumption per 2 gallons transferred | C4: kWH
A5: TR4 | B5: Maximum throughput capacity of the system | C5: GPH
A6: TR5 | B6: Distribution Uniformity (DU) coefficient | C6: Percentage
A7: TR6 | B7: Variance in water application rates between zones | C7: GPM
A8: TR7 | B8: Number of dry or overwatered spots detected | C8: Count
A9: TR8 | B9: System reliability (uptime percentage) | C9: Percentage
A10: TR9 | B10: Physical force required to operate controls | C10: lbf
A11: TR10 | B11: Number of manual operations per watering cycle | C11: Count
A12: TR11 | B12: Total operator time per watering session | C12: Minutes
... A85: TR84 | B85: Number of weather-related malfunctions per year | C85: Count

Sheet CR-TR_Interactions
B1: C1 | C1: C2 | D1: C3 | E1: C4 | F1: C5 | G1: C6 | H1: C7 | I1: C8 | J1: C9 | K1: C10 | L1: C11 | M1: C12 | N1: C13 | O1: C14 | P1: C15 | Q1: C16 | R1: C17 | S1: C18 | T1: C19 | U1: C20 | V1: C21 | W1: SUM | X1: Weight | Y1: Rank | Z1: Grading
A2: TR1 | B2: 9 | C2: 0 | D2: 0 | E2: 0 | F2: 9 | G2: 9 | H2: 1 | I2: 0 | J2: 0 | K2: 0 | L2: 0 | M2: 0 | N2: 3 | O2: 1 | P2: 0 | Q2: 1 | R2: 3 | S2: 3 | T2: 0 | U2: 3 | V2: 0 | W2: 139.75 | X2: 0.013199216 | Y2: 31 | Z2: Strong (9)
A3: TR2 | B3: 9 | C3: 1 | D3: 0 | E3: 3 | F3: 9 | G3: 9 | H3: 1 | I3: 0 | J3: 0 | K3: 0 | L3: 0 | M3: 0 | N3: 3 | O3: 3 | P3: 3 | Q3: 3 | R3: 3 | S3: 3 | T3: 0 | U3: 3 | V3: 0 | W3: 177.75 | X3: 0.016788269 | Y3: 11 | Z3: Medium (3)
A4: TR3 | B4: 3 | C4: 0 | D4: 0 | E4: 0 | F4: 3 | G4: 3 | H4: 0 | I4: 0 | J4: 0 | K4: 0 | L4: 0 | M4: 0 | N4: 9 | O4: 1 | P4: 1 | Q4: 3 | R4: 9 | S4: 9 | T4: 0 | U4: 1 | V4: 0 | W4: 138.75 | X4: 0.013104767 | Y4: 32 | Z4: Weak (1)
A5: TR4 | B5: 9 | C5: 3 | D5: 0 | E5: 3 | F5: 9 | G5: 3 | H5: 1 | I5: 0 | J5: 0 | K5: 0 | L5: 1 | M5: 0 | N5: 3 | O5: 3 | P5: 0 | Q5: 3 | R5: 3 | S5: 3 | T5: 0 | U5: 3 | V5: 1 | W5: 161.25 | X5: 0.015229865 | Y5: 19 | Z5: None (0)
A6: TR5 | B6: 1 | C6: 9 | D6: 0 | E6: 3 | F6: 3 | G6: 1 | H6: 1 | I6: 0 | J6: 0 | K6: 0 | L6: 0 | M6: 0 | N6: 3 | O6: 3 | P6: 0 | Q6: 1 | R6: 3 | S6: 1 | T6: 0 | U6: 3 | V6: 0 | W6: 104.25 | X6: 0.0098462846 | Y6: 53
A7: TR6 | B7: 1 | C7: 9 | D7: 0 | E7: 3 | F7: 3 | G7: 1 | H7: 1 | I7: 0 | J7: 0 | K7: 0 | L7: 0 | M7: 0 | N7: 3 | O7: 1 | P7: 0 | Q7: 1 | R7: 3 | S7: 1 | T7: 0 | U7: 3 | V7: 0 | W7: 98.75 | X7: 0.0093268164 | Y7: 60
A8: TR7 | B8: 0 | C8: 9 | D8: 0 | E8: 3 | F8: 1 | G8: 1 | H8: 0 | I8: 0 | J8: 0 | K8: 0 | L8: 0 | M8: 0 | N8: 3 | O8: 1 | P8: 0 | Q8: 3 | R8: 3 | S8: 1 | T8: 0 | U8: 1 | V8: 0 | W8: 87.25 | X8: 0.0082406555 | Y8: 62
A9: TR8 | B9: 3 | C9: 3 | D9: 3 | E9: 3 | F9: 1 | G9: 3 | H9: 3 | I9: 0 | J9: 0 | K9: 3 | L9: 3 | M9: 1 | N9: 3 | O9: 1 | P9: 0 | Q9: 3 | R9: 9 | S9: 9 | T9: 0 | U9: 3 | V9: 3 | W9: 194.25 | X9: 0.018346674 | Y9: 5
A10: TR9 | B10: 1 | C10: 0 | D10: 9 | E10: 0 | F10: 0 | G10: 0 | H10: 9 | I10: 9 | J10: 1 | K10: 0 | L10: 0 | M10: 1 | N10: 1 | O10: 0 | P10: 0 | Q10: 1 | R10: 1 | S10: 1 | T10: 0 | U10: 3 | V10: 1 | W10: 115.75 | X10: 0.010932446 | Y10: 50
A11: TR10 | B11: 1 | C11: 0 | D11: 9 | E11: 0 | F11: 1 | G11: 3 | H11: 9 | I11: 3 | J11: 3 | K11: 3 | L11: 0 | M11: 1 | N11: 3 | O11: 0 | P11: 0 | Q11: 3 | R11: 3 | S11: 3 | T11: 0 | U11: 3 | V11: 0 | W11: 158 | X11: 0.014922906 | Y11: 21
A12: TR11 | B12: 3 | C12: 0 | D12: 9 | E12: 0 | F12: 1 | G12: 3 | H12: 3 | I12: 3 | J12: 3 | K12: 3 | L12: 0 | M12: 0 | N12: 3 | O12: 0 | P12: 0 | Q12: 3 | R12: 3 | S12: 3 | T12: 0 | U12: 3 | V12: 0 | W12: 141.75 | X12: 0.013388114 | Y12: 28
A13: TR12 | B13: 1 | C13: 0 | D13: 9 | E13: 0 | F13: 0 | G13: 0 | H13: 9 | I13: 1 | J13: 1 | K13: 0 | L13: 0 | M13: 1 | N13: 1 | O13: 0 | P13: 0 | Q13: 1 | R13: 1 | S13: 1 | T13: 0 | U13: 1 | V13: 0 | W13: 94.5 | X13: 0.0089254091 | Y13: 61
A14: TR13 | B14: 9 | C14: 9 | D14: 0 | E14: 9 | F14: 9 | G14: 9 | H14: 0 | I14: 0 | J14: 0 | K14: 0 | L14: 0 | M14: 0 | N14: 3 | O14: 1 | P14: 3 | Q14: 1 | R14: 3 | S14: 3 | T14: 0 | U14: 3 | V14: 3 | W14: 221 | X14: 0.020873179 | Y14: 2
A15: TR14 | B15: 9 | C15: 9 | D15: 0 | E15: 9 | F15: 9 | G15: 9 | H15: 0 | I15: 0 | J15: 0 | K15: 0 | L15: 0 | M15: 0 | N15: 3 | O15: 1 | P15: 0 | Q15: 1 | R15: 3 | S15: 1 | T15: 0 | U15: 1 | V15: 1 | W15: 192 | X15: 0.018134164 | Y15: 6
A16: TR15 | B16: 3 | C16: 9 | D16: 0 | E16: 9 | F16: 9 | G16: 9 | H16: 0 | I16: 0 | J16: 0 | K16: 0 | L16: 0 | M16: 0 | N16: 3 | O16: 1 | P16: 3 | Q16: 1 | R16: 3 | S16: 3 | T16: 0 | U16: 1 | V16: 0 | W16: 180.25 | X16: 0.017024391 | Y16: 9
A17: TR16 | B17: 3 | C17: 9 | D17: 0 | E17: 9 | F17: 9 | G17: 9 | H17: 0 | I17: 0 | J17: 0 | K17: 0 | L17: 0 | M17: 0 | N17: 3 | O17: 1 | P17: 3 | Q17: 1 | R17: 1 | S17: 1 | T17: 0 | U17: 3 | V17: 3 | W17: 184 | X17: 0.017378574 | Y17: 8
... A85: TR84 | B85: 1 | C85: 3 | D85: 0 | E85: 0 | F85: 1 | G85: 3 | H85: 0 | I85: 0 | J85: 0 | K85: 0 | L85: 1 | M85: 0 | N85: 3 | O85: 1 | P85: 0 | Q85: 3 | R85: 3 | S85: 1 | T85: 3 | U85: 9 | V85: 9 | W85: 135 | X85: 0.012750584 | Y85: 35

Sheet TR-TR_interaction
B1: TR1 | C1: TR2 | D1: TR3 | E1: TR4 | F1: TR5 | G1: TR6 | H1: TR7 | I1: TR8 | J1: TR9 | K1: TR10 | L1: TR11 | M1: TR12 | N1: TR13 | O1: TR14 | P1: TR15 | Q1: TR16 | R1: TR17 | S1: TR18 | T1: TR19 | U1: TR20 | V1: TR21 | W1: TR22 | X1: TR23 | Y1: TR24 | Z1: TR25 | AA1: TR26 | AB1: TR27 | AC1: TR28 | AD1: TR29 | AE1: TR30 | AF1: TR31 | AG1: TR32 | AH1: TR33 | AI1: TR34 | AJ1: TR35 | AK1: TR36 | AL1: TR37 | AM1: TR38 | AN1: TR39 | AO1: TR40 | AP1: TR41 | AQ1: TR42 | AR1: TR43 | AS1: TR44 | AT1: TR45 | AU1: TR46 | AV1: TR47 | AW1: TR48 | AX1: TR49 | AY1: TR50 | AZ1: TR51 | BA1: TR52 | BB1: TR53 | BC1: TR54 | BD1: TR55 | BE1: TR56 | BF1: TR57 | BG1: TR58 | BH1: TR59 | BI1: TR60 | BJ1: TR61 | BK1: TR62 | BL1: TR63 | BM1: TR64 | BN1: TR65 | BO1: TR66 | BP1: TR67 | BQ1: TR68 | BR1: TR69 | BS1: TR70 | BT1: TR71 | BU1: TR72 | BV1: TR73 | BW1: TR74 | BX1: TR75 | BY1: TR76 | BZ1: TR77 | CA1: TR78 | CB1: TR79 | CC1: TR80 | CD1: TR81 | CE1: TR82 | CF1: TR83 | CG1: TR84
A2: TR1
A3: TR2 | B3: +
A4: TR3 | B4: - | C4: -
A5: TR4 | B5: + | C5: + | D5: +
A6: TR5 | B6: o | C6: - | D6: o | E6: +
A7: TR6 | B7: o | C7: - | D7: o | E7: + | F7: +
A8: TR7 | B8: o | C8: o | D8: o | E8: o | F8: + | G8: +
A9: TR8 | B9: + | C9: + | D9: + | E9: - | F9: o | G9: o | H9: o
A10: TR9 | B10: - | C10: o | D10: o | E10: o | F10: - | G10: - | H10: - | I10: o
A11: TR10 | B11: + | C11: - | D11: o | E11: o | F11: - | G11: - | H11: - | I11: o | J11: -
A12: TR11 | B12: + | C12: - | D12: + | E12: + | F12: + | G12: + | H12: + | I12: o | J12: - | K12: +
A13: TR12 | B13: - | C13: - | D13: o | E13: + | F13: - | G13: - | H13: - | I13: o | J13: + | K13: + | L13: +
A14: TR13 | B14: + | C14: + | D14: + | E14: + | F14: + | G14: + | H14: + | I14: + | J14: - | K14: + | L14: - | M14: o
A15: TR14 | B15: - | C15: - | D15: o | E15: - | F15: - | G15: - | H15: - | I15: - | J15: o | K15: + | L15: + | M15: o | N15: -
A16: TR15 | B16: + | C16: + | D16: + | E16: o | F16: + | G16: + | H16: + | I16: + | J16: - | K16: + | L16: - | M16: o | N16: o | O16: +
A17: TR16 | B17: + | C17: - | D17: + | E17: - | F17: + | G17: + | H17: + | I17: - | J17: - | K17: + | L17: + | M17: o | N17: + | O17: - | P17: +
A18: TR17 | B18: o | C18: + | D18: + | E18: + | F18: + | G18: + | H18: + | I18: o | J18: - | K18: + | L18: - | M18: + | N18: + | O18: - | P18: + | Q18: -
A19: TR18 | B19: o | C19: + | D19: + | E19: + | F19: + | G19: + | H19: + | I19: o | J19: - | K19: + | L19: - | M19: + | N19: + | O19: - | P19: + | Q19: - | R19: +
A20: TR19 | B20: + | C20: + | D20: + | E20: + | F20: + | G20: + | H20: + | I20: o | J20: - | K20: + | L20: - | M20: + | N20: + | O20: - | P20: + | Q20: - | R20: + | S20: +
A21: TR20 | B21: + | C21: + | D21: + | E21: + | F21: + | G21: + | H21: + | I21: + | J21: - | K21: + | L21: - | M21: + | N21: + | O21: - | P21: + | Q21: - | R21: + | S21: + | T21: +
A22: TR21 | B22: + | C22: + | D22: + | E22: - | F22: o | G22: o | H22: o | I22: + | J22: o | K22: + | L22: - | M22: + | N22: + | O22: - | P22: + | Q22: - | R22: + | S22: + | T22: + | U22: +
A23: TR22 | B23: + | C23: + | D23: + | E23: o | F23: o | G23: o | H23: o | I23: + | J23: o | K23: + | L23: - | M23: + | N23: + | O23: - | P23: + | Q23: - | R23: + | S23: + | T23: + | U23: + | V23: +
A24: TR23 | B24: o | C24: - | D24: o | E24: o | F24: + | G24: + | H24: + | I24: + | J24: o | K24: o | L24: o | M24: o | N24: o | O24: o | P24: o | Q24: o | R24: + | S24: + | T24: + | U24: + | V24: + | W24: +
A25: TR24 | B25: + | C25: + | D25: + | E25: + | F25: - | G25: - | H25: - | I25: - | J25: o | K25: + | L25: - | M25: o | N25: + | O25: - | P25: + | Q25: - | R25: + | S25: + | T25: + | U25: + | V25: + | W25: + | X25: +
A26: TR25 | B26: + | C26: + | D26: o | E26: + | F26: o | G26: o | H26: o | I26: o | J26: - | K26: + | L26: - | M26: + | N26: o | O26: - | P26: o | Q26: - | R26: + | S26: o | T26: + | U26: + | V26: o | W26: o | X26: o | Y26: +
A27: TR26 | B27: + | C27: o | D27: o | E27: + | F27: + | G27: + | H27: + | I27: + | J27: - | K27: + | L27: + | M27: o | N27: o | O27: - | P27: o | Q27: - | R27: + | S27: o | T27: + | U27: + | V27: o | W27: o | X27: o | Y27: + | Z27: +
A28: TR27 | B28: o | C28: o | D28: o | E28: o | F28: + | G28: + | H28: + | I28: o | J28: - | K28: + | L28: - | M28: o | N28: + | O28: - | P28: + | Q28: - | R28: + | S28: + | T28: + | U28: + | V28: + | W28: + | X28: + | Y28: + | Z28: + | AA28: +
A29: TR28 | B29: + | C29: - | D29: o | E29: o | F29: - | G29: - | H29: - | I29: o | J29: o | K29: + | L29: + | M29: - | N29: + | O29: - | P29: + | Q29: - | R29: + | S29: + | T29: + | U29: + | V29: + | W29: + | X29: o | Y29: + | Z29: + | AA29: o | AB29: +
A30: TR29 | B30: - | C30: o | D30: o | E30: o | F30: - | G30: - | H30: - | I30: o | J30: - | K30: + | L30: + | M30: - | N30: + | O30: - | P30: + | Q30: - | R30: + | S30: + | T30: + | U30: + | V30: + | W30: + | X30: o | Y30: o | Z30: o | AA30: o | AB30: + | AC30: +
A31: TR30 | B31: + | C31: + | D31: + | E31: + | F31: + | G31: + | H31: + | I31: o | J31: - | K31: + | L31: + | M31: - | N31: + | O31: - | P31: + | Q31: - | R31: + | S31: + | T31: + | U31: + | V31: + | W31: + | X31: o | Y31: + | Z31: + | AA31: + | AB31: + | AC31: + | AD31: +
A32: TR31 | B32: + | C32: o | D32: o | E32: + | F32: + | G32: + | H32: + | I32: o | J32: o | K32: o | L32: - | M32: o | N32: + | O32: - | P32: + | Q32: - | R32: + | S32: + | T32: + | U32: + | V32: + | W32: + | X32: + | Y32: o | Z32: o | AA32: + | AB32: + | AC32: + | AD32: + | AE32: +
A33: TR32 | B33: o | C33: o | D33: o | E33: o | F33: o | G33: o | H33: o | I33: o | J33: - | K33: + | L33: - | M33: + | N33: + | O33: - | P33: o | Q33: o | R33: o | S33: o | T33: o | U33: o | V33: o | W33: o | X33: o | Y33: o | Z33: o | AA33: o | AB33: + | AC33: + | AD33: + | AE33: + | AF33: +
A34: TR33 | B34: - | C34: o | D34: o | E34: o | F34: o | G34: o | H34: o | I34: o | J34: o | K34: + | L34: + | M34: o | N34: o | O34: o | P34: o | Q34: o | R34: o | S34: o | T34: o | U34: o | V34: o | W34: o | X34: o | Y34: o | Z34: - | AA34: o | AB34: + | AC34: + | AD34: + | AE34: + | AF34: + | AG34: +
A35: TR34 | B35: + | C35: o | D35: o | E35: o | F35: o | G35: o | H35: o | I35: o | J35: o | K35: o | L35: + | M35: o | N35: o | O35: o | P35: o | Q35: o | R35: o | S35: o | T35: o | U35: o | V35: o | W35: o | X35: o | Y35: + | Z35: + | AA35: + | AB35: + | AC35: + | AD35: + | AE35: + | AF35: + | AG35: + | AH35: +
A36: TR35 | B36: + | C36: - | D36: o | E36: o | F36: - | G36: - | H36: - | I36: o | J36: - | K36: + | L36: + | M36: - | N36: + | O36: - | P36: + | Q36: - | R36: + | S36: + | T36: + | U36: + | V36: + | W36: + | X36: o | Y36: + | Z36: + | AA36: o | AB36: + | AC36: + | AD36: + | AE36: + | AF36: o | AG36: + | AH36: + | AI36: +
A37: TR36 | B37: + | C37: o | D37: o | E37: + | F37: + | G37: + | H37: + | I37: o | J37: o | K37: + | L37: - | M37: o | N37: o | O37: o | P37: o | Q37: o | R37: o | S37: o | T37: o | U37: o | V37: o | W37: o | X37: o | Y37: + | Z37: + | AA37: + | AB37: + | AC37: + | AD37: + | AE37: + | AF37: + | AG37: + | AH37: + | AI37: + | AJ37: +
A38: TR37 | B38: + | C38: + | D38: + | E38: o | F38: + | G38: + | H38: + | I38: + | J38: o | K38: + | L38: - | M38: o | N38: + | O38: - | P38: + | Q38: - | R38: + | S38: - | T38: - | U38: + | V38: + | W38: - | X38: + | Y38: + | Z38: o | AA38: + | AB38: + | AC38: o | AD38: + | AE38: + | AF38: o | AG38: o | AH38: o | AI38: + | AJ38: + | AK38: +
A39: TR38 | B39: + | C39: + | D39: + | E39: - | F39: + | G39: + | H39: + | I39: + | J39: - | K39: + | L39: - | M39: o | N39: + | O39: - | P39: + | Q39: - | R39: + | S39: - | T39: - | U39: + | V39: + | W39: + | X39: + | Y39: + | Z39: o | AA39: + | AB39: + | AC39: o | AD39: + | AE39: + | AF39: o | AG39: o | AH39: + | AI39: + | AJ39: + | AK39: + | AL39: +
A40: TR39 | B40: + | C40: - | D40: + | E40: o | F40: - | G40: - | H40: - | I40: - | J40: o | K40: + | L40: + | M40: - | N40: + | O40: - | P40: + | Q40: - | R40: + | S40: - | T40: - | U40: + | V40: + | W40: + | X40: + | Y40: + | Z40: o | AA40: + | AB40: + | AC40: o | AD40: + | AE40: + | AF40: o | AG40: o | AH40: + | AI40: + | AJ40: + | AK40: + | AL40: + | AM40: +
...

Sheet CR-TR_Importance
